Workbook
Name BE_shifting: Ranges!$D$4:$D$6
Name DR_shifting: Ranges!$E$4:$E$6
Name none: Ranges!$C$4:$C$6
Name ST_storage: Ranges!$F$5:$F$7

Sheet IESA-Opt database
C3: IESA - NL' energy system database TRANSFORM
D5: By:
E6: TNO Energy and Material Transition
E7: Universiteit Utrecht (UU)
E8: Planbureau voor de Leefomgeving (PBL)
E9: Rijksuniveriteit Groningen (RUG)
D11: Contact persons:
E12: Kira West
E13: Amir Fattahi
D16: Generalities:
E17: All the costs are expressed in 2019 euros [€_2019]. Please take this into consideration when updating data. For this pupose a conversion table is provided in data sources sheet. The red tabs contain data related to the definition of the activities, and their projected volumes within the scenario. The blue tabs contain the technologies, and their descriptions in terms of the required modelling parameters. The yellow tabs contain other parameters relevant for the functioning of the model and this excel file. The data contained in this excel file represents one scenario only. This means that each scenario explored must have its own excel data file.
D19: Name of the scenario:
E20: IESA TRANSFORM Scenario
D22: Storyline of the scenario:

Sheet Data Sources
A1: List of data sources used to build and update the database | H1: Currency conversion
H2: Auxiliar for € adjustment | J2: Data source
A3: No. | B3: Source name | C3: Description | D3: Year | E3: Link to public source [if available] | F3: Link to publication [if available] | H3: Year of € | I3: Equivalent in €_2019 | J3: [ref No.]
A4: 1 | B4: PBL's ENSYSI model database | C4: Data collected from different sources by PBL to build ENSYSI. | D4: 2015 | E4: NA | F4: EFFECTEN VAN DE ENERGIETRANSITIE OP DE REGIONALE ARBEIDSMARKT – EEN QUICKSCAN | H4: 2010 | I4: 0.88715401 | J4: [8]
A5: 2 | B5: COMPETES model database | C5: Data collected from different sources by PBL/ECN based on TYNDP (MAF 2016 & Sustainable Transition) | D5: 2020 | E5: NA | F5: Capacity vs energy subsidies for promoting renewable investment: Benefits and costs for the EU power market | H5: 2011 | I5: 0.90684883 | J5: [8]
A6: 3 | B6: TNO factsheets | C6: Large scale alkalyne electrolyzer factsheet | D6: 2019 | E6: Electrolyzer factsheet | F6: NA | H6: 2012 | I6: 0.93186657 | J6: [8]
A7: 4 | B7: TNO factsheets | C7: Data collected by Remko Detz into the set of factsheets | D7: 2019 | E7: DAC factsheet | F7: NA | H7: 2013 | I7: 0.95253726 | J7: [8]
A8: 5 | B8: TNO factsheets | C8: Data collected by Remko Detz into the set of factsheets | D8: 2019 | E8: FT facsheet (not yet online) | F8: NA | H8: 2014 | I8: 0.96061036 | J8: [8]
A9: 6 | B9: TNO factsheets | C9: Data collected by Remko Detz into the set of factsheets | D9: 2019 | E9: Methanol path factsheet (not yet online) | F9: NA | H9: 2015 | I9: 0.95892477 | J9: [8]
A10: 7 | B10: Cost of storage technologies | C10: Publication (Zakeri and Syri, 2015) | D10: 2015 | E10: NA | F10: Electrical energy storage systems: A comparative life cycle cost analysis | H10: 2016 | I10: 0.96132009 | J10: [8]
A11: 8 | B11: Euro inflation tool | C11: Source from where the euro adjustment parameters where obtained for different years | D11: 2020 | E11: inflationtool | F11: NA | H11: 2017 | I11: 0.97187722 | J11: [8]
A12: 9 | B12: OPERA model database | C12: Data collected from different sources by ECN | D12: 2015 | E12: NA | F12: FLEXNET Report OPERA section | H12: 2018 | I12: 0.9850071 | J12: [8]
A13: 10 | B13: METIS T4 | C13: Maximum clearing price in the APX day ahead electricity market accordingly with European Comission regulations | D13: 2016 | E13: NA | F13: METIS T4 | H13: 2019 | I13: 1 | J13: [8]
A14: 11 | B14: POTENCIA Central Scenario NL | C14: Assumptions used for the services activity volumes in the POTENCIA scenarios by JRC. This data was used to define the heat intensity of the service sectors as well as the drivers. The drivers were directly extracted from the CENTRAL SCENARIO NL database. And the intensities were combined with ENSYSI data to provide the water heating plus HDD function for the heat intensity. The reference HDD used for the reference parameters was of 2900 HDD. | D14: 2019 | E14: Database access | F14: POTENCIA Scenario Report
A15: 12 | B15: POTENCIA Central Scenario | C15: Assumptions and data used for the Transport sectors in the POTENCIA scenario by JRC. We grouped some of the activities and proportionally adjusted the parameters from the POTENCIA database. Most of the data was extracted from the Annual Reports>Transport folder. Given the lack of data on capital costs, data was extracted from different sources and compared/callibrated to provide grouped annual costs similar to the reported by POTENCIA. | D15: 2019 | E15: Database access | F15: POTENCIA Scenario Report
A16: 13 | B16: Methodology to quantify transport emissions | C16: Source to justify accounting only for LTO in aviation within national emissions. | D16: 2019 | F16: Methods for calculating the emissions of transport in the Netherlands
A17: 14 | B17: LTO vs CCD emissions | C17: Source to justify the proxies used for LTO and CCD emissions in aviation for Intra and Extra EU flights. It is not the perfect source, but it works for now. We are using it for the parameters regarding the share of international emmisions in aviation. | D17: 2019 | F17: Paper showing EEA data
A18: 15 | B18: POTENCIA Central Scenario NL | C18: Data extracted to define residential, industry and agriculture activity volumes in the reference scenario | D18: 2019 | E18: Database access | F18: POTENCIA Scenario Report
A19: 16 | B19: Change in HDD in EU countries | C19: Publication (Spinioni et al, 2018) | D19: 2018 | E19: NA | F19: Changes of heating and cooling degree-days in Europe from 1981 to 2100
A20: 17 | B20: ENSPRESO Biomass | C20: Projection on potentials for biomass availability and expected energy prices. Reference scenario. | D20: 2019 | E20: Database access | F20: Bioenergy potentials for EU and neighbouring countries
A21: 18 | B21: Climate and Energy Outlook 2019 | C21: Use of the expected ETS prices developments (2020-2030). | D21: 2019 | E21: KEV table attachment | F21: Climate and Energy Outlook 2019
A22: 19 | B22: CBP ETS valuation projections | C22: Long term projection scenarios on ETS price according with CBP. Mixed with KEV 19 available data on 2020-2030, to complement the long term 2050 picture. | D22: 2016 | F22: Valuation of CO2 emissions in CBA: implications of the scenario study Welfare, Prosperity and the Human Environment
A23: 20 | B23: ENTSOG network | C23: Information about interconnection nodes to the national gas network | D23: 2019 | E23: ENTSOG network map
A24: 21 | B24: NLOG Gas production data | C24: Data about the production of dutch gas fields. Complemented with the policy of closure of the Groningen field by 2022. | D24: 2015 | E24: NLOG data | F24: SP Global Analysis on groningen field closure
A25: 22 | B25: LNG Price estimation | C25: Collection of sources for the estimation of the LNG gas price in Europe | D25: 2019 | F25: CSIS article gathering data from EUROSTAT and US Department of Energy
A26: 23 | B26: TAQA Bergermeer Gas Storage | C26: Operational and project costs data of the operational TAQA gas storage plant | D26: 2015/2020 | E26: TAQA Operational figures | F26: TAQA Project
A27: 24 | B27: Zuidwending Gas Buffer | C27: Operational and project costs data of the operational Zuidwending gas storage plant | D27: 2006/2020 | E27: Public data | F27: Project description
A28: 25 | B28: NL GHG Inventory Report | C28: GHG Emissions in the Netherlands from 1990 to 2017 extracted from the national inventory 2019 | D28: 2019 | F28: Publication with data in tables
A29: 26 | B29: nonCO2 GHG emissions MACCs | C29: Publication with the MACC curves evolution until 2100 for most important nonCO2 GHG emissions in the World. | D29: 2019 | E29: Public data | F29: Publication
A30: 27 | B30: HFC emissions projections | C30: Publication with the expected development of HFC emissions in the world | D30: 2009 | F30: Publication
A31: 28 | B31: Trends in cattle numbers | C31: Historcal trends of cattle evolution in the Netherlands used as criteria to define the evolution of cattle related emissions. This database proposes that cattle numbers will decrease in the future. | D31: 2019 | E31: CBS data
A32: 29 | B32: Trends in agricultural land use in the Netherlands | C32: Thesis from VU exploring land use change in the Netherlands. This study is used to define the driver in N2O agricultural emmisions which assumes a 10% decrease in 2050. | D32: 2012 | F32: Thesis
A33: 30 | B33: Low carbon electricity generation costs | C33: Database from JRC on cost prametes of green electricity sources in Europe | D33: 2017 | E33: Database | F33: Publication
A34: 31 | B34: Compressor costs | C34: Paper with pipeline compressor costs in the USA | D34: 2018 | F34: Publication
A35: 32 | B35: CE Delft Scenarios | C35: Grid for the future scenario report | D35: 2017 | F35: Publication
A36: 33 | B36: TNO Scenarios | C36: Scenarios for a climate neutral energy system (adapt and transform data) | D36: 2020 | E36: Data | F36: Publication
A37: 34 | B37: Nuclear generation data | C37: Corrigendum from nuclear industry (Kan et al. paper) | D37: 2020 | F37: Publication
A38: 35 | B38: Petrochemical sector | C38: Petroleum products balance sheet; supply, consumption and stock | D38: 2017 | E38: Data
A39: 36 | B39: CBS Energy Balance | C39: Energy balance sheet; supply, transformation and consumption | D39: 2019 | E39: Data
A40: 37 | B40: Steel production ECN-MIDDEN | C40: 2050 Decarbonisation of the Dutch Steelmaking Industry (Note: Coke oven gas generation is added to the gas network in the balance used in IESA-Opt) | D40: 2019 | F40: Master Thesis
...

Sheet Activities
A1: These markets are the activity levels that must be met by the model in each year. The activity balance of the technologies must be equal to these.
C2: Evolution of driver in time | J2: Data source
A3: External drivers (not in AIMMS) | B3: UoA | C3: =Parameters!$B$13 -> 2022 | D3: 2025 | E3: 2030 | F3: 2035 | G3: 2040 | H3: 2045 | I3: 2050 | J3: [ref No.]
A4: Population | B4: [Mpp] | C4: 17.59 | D4: 18.347 | E4: 18.757 | F4: 18.977 | G4: 19.063 | H4: 19.042 | I4: 18.958 | J4: CBS statline (bevolking; kerncijfers), UN Population Division, World Population Prospects 2024
A5: Gross Domestic Product | B5: [M€_2022] | C5: 1146886 | D5: 1167902 | E5: 1274004 | F5: 1366385 | G5: 1477170 | H5: 1608711 | I5: 1747307 | J5: OECD Real GDP long-term forecast
A6: Heat degree days | B6: [HDD] | C6: 2900 | D6: 2850 | E6: 2800 | F6: 2710 | G6: 2620 | H6: 2530 | I6: 2440 | J6: [16]
C7: Evolution of volumes in time | J7: Maximum transformation | K7: Dispatch resolution | L7: Activity Type | M7: Node | N7: Target | O7: Energy Label | P7: Emission Factors | Q7: Share of neutrality | R7: Data source
A8: Activities | B8: UoA | C8: =Parameters!$B$13 -> 2022 | D8: 2025 | E8: 2030 | F8: 2035 | G8: 2040 | H8: 2045 | I8: 2050 | J8: [%/5years] | K8: [type] | L8: [type] | M8: [type] | N8: [y/n] | O8: [type] | P8: [Mton_CO2/PJ] | Q8: [%] | R8: [ref No.]
A9: Electricity demand - Residential | B9: [PJ] | C9: 80.1 | D9: =(D$4/C$4)*C9 -> 83.547169 | E9: =(E$4/D$4)*D9 -> 85.414196 | F9: =(F$4/E$4)*E9 -> 86.416015 | G9: =(G$4/F$4)*F9 -> 86.807635 | H9: =(H$4/G$4)*G9 -> 86.712007 | I9: =(I$4/H$4)*H9 -> 86.329494 | K9: yearly | L9: Driver | M9: NL | N9: 0 | O9: NA | P9: NA | Q9: NA
A10: Houses - Residential Flats | B10: [khouses] | C10: 2916 | D10: =(D4/C4)*C10 -> 3041.4924 | E10: =(E4/D4)*D10 -> 3109.4606 | F10: =(F4/E4)*E10 -> 3145.9313 | G10: =(G4/F4)*F10 -> 3160.1881 | H10: =(H4/G4)*G10 -> 3156.7068 | I10: =(I4/H4)*H10 -> 3142.7816 | K10: yearly | L10: Driver | M10: NL | N10: 0 | O10: NA | P10: NA | Q10: NA
A11: Houses - Residential Terrace | B11: [khouses] | C11: =1019+2361 -> 3380 | D11: =(D4/C4)*C11 -> 3525.4611 | E11: =(E4/D4)*D11 -> 3604.2445 | F11: =(F4/E4)*E11 -> 3646.5185 | G11: =(G4/F4)*F11 -> 3663.0438 | H11: =(H4/G4)*G11 -> 3659.0085 | I11: =(I4/H4)*H11 -> 3642.8675 | K11: yearly | L11: Driver | M11: NL | N11: 0 | O11: NA | P11: NA | Q11: NA
A12: Houses - Residential Dwellings | B12: [khouses] | C12: =1043+704 -> 1747 | D12: =(D4/C4)*C12 -> 1822.1836 | E12: =(E4/D4)*D12 -> 1862.9039 | F12: =(F4/E4)*E12 -> 1884.7538 | G12: =(G4/F4)*F12 -> 1893.2951 | H12: =(H4/G4)*G12 -> 1891.2094 | I12: =(I4/H4)*H12 -> 1882.8667 | K12: yearly | L12: Driver | M12: NL | N12: 0 | O12: NA | P12: NA | Q12: NA
A13: Electricity demand - Services | B13: [PJ] | C13: 124.9 | D13: =D$5/C$5*C13 -> 127.18872 | E13: =E$5/D$5*D13 -> 138.74361 | F13: =F$5/E$5*E13 -> 148.80423 | G13: =G$5/F$5*F13 -> 160.86911 | H13: =H$5/G$5*G13 -> 175.1944 | I13: =I$5/H$5*H13 -> 190.288 | K13: yearly | L13: Driver | M13: NL | N13: 0 | O13: NA | P13: NA | Q13: NA
A14: Space - Services | B14: [Mm2] | C14: =430*1.0203 -> 438.729 | D14: =D$5/C$5*C14 -> 446.76845 | E14: =E$5/D$5*D14 -> 487.35663 | F14: =F$5/E$5*E14 -> 522.696 | G14: =G$5/F$5*F14 -> 565.07562 | H14: =H$5/G$5*G14 -> 615.39523 | I14: =I$5/H$5*H14 -> 668.41365 | K14: yearly | L14: Driver | M14: NL | N14: 0 | O14: NA | P14: NA | Q14: NA
A15: Electricity demand - Agricuture | B15: [PJ] | C15: 25.2 | D15: =D$5/C$5*C15 -> 25.661775 | E15: =E$5/D$5*D15 -> 27.993106 | F15: =F$5/E$5*E15 -> 30.022951 | G15: =G$5/F$5*F15 -> 32.457179 | H15: =H$5/G$5*G15 -> 35.347469 | I15: =I$5/H$5*H15 -> 38.392775 | K15: yearly | L15: Driver | M15: NL | N15: 0 | O15: NA | P15: NA | Q15: NA
A16: Heat demand - Agriculture | B16: [PJ] | C16: =39.7+14.2+20.7*0.9 -> 72.53 | D16: =C16 -> 72.53 | E16: =D16 -> 72.53 | F16: =E16 -> 72.53 | G16: =F16 -> 72.53 | H16: =G16 -> 72.53 | I16: =H16 -> 72.53 | K16: yearly | L16: Driver | M16: NL | N16: 0 | O16: NA | P16: NA | Q16: NA
A17: Machinery - Agriculture | B17: [PJ] | C17: 25.2 | D17: =C17 -> 25.2 | E17: =D17 -> 25.2 | F17: =E17 -> 25.2 | G17: =F17 -> 25.2 | H17: =G17 -> 25.2 | I17: =H17 -> 25.2 | K17: yearly | L17: Driver | M17: NL | N17: 0 | O17: NA | P17: NA | Q17: NA
A18: Steel production - Basic Metals Industry | B18: [Mton_Steel] | C18: 6.143 | D18: =(C18)*(1+$T$2)^(D$8-C$8) -> 6.143 | E18: =(D18)*(1+$T$2)^(E$8-D$8) -> 6.143 | F18: =(E18)*(1+$T$2)^(F$8-E$8) -> 6.143 | G18: =(F18)*(1+$T$2)^(G$8-F$8) -> 6.143 | H18: =(G18)*(1+$T$2)^(H$8-G$8) -> 6.143 | I18: =(H18)*(1+$T$2)^(I$8-H$8) -> 6.143 | K18: yearly | L18: Driver | M18: NL | N18: 0 | O18: NA | P18: NA | Q18: NA
A19: Nitric Acid production - Fertilizers Industry | B19: [Mton_AN] | C19: 2.4 | D19: =(C19)*(1+$T$2)^(D$8-C$8) -> 2.4 | E19: =(D19)*(1+$T$2)^(E$8-D$8) -> 2.4 | F19: =(E19)*(1+$T$2)^(F$8-E$8) -> 2.4 | G19: =(F19)*(1+$T$2)^(G$8-F$8) -> 2.4 | H19: =(G19)*(1+$T$2)^(H$8-G$8) -> 2.4 | I19: =(H19)*(1+$T$2)^(I$8-H$8) -> 2.4 | K19: yearly | L19: Driver | M19: NL | N19: 0 | O19: NA | P19: NA | Q19: NA
A20: Urea production - Fertilizers Industry | B20: [Mton_Urea] | C20: 1.8 | D20: =(C20)*(1+$T$2)^(D$8-C$8) -> 1.8 | E20: =(D20)*(1+$T$2)^(E$8-D$8) -> 1.8 | F20: =(E20)*(1+$T$2)^(F$8-E$8) -> 1.8 | G20: =(F20)*(1+$T$2)^(G$8-F$8) -> 1.8 | H20: =(G20)*(1+$T$2)^(H$8-G$8) -> 1.8 | I20: =(H20)*(1+$T$2)^(I$8-H$8) -> 1.8 | K20: yearly | L20: Driver | M20: NL | N20: 0 | O20: NA | P20: NA | Q20: NA
A21: Other Ammonia based fertilizers - Fertilizers Industry | B21: [Mton_NH3] | C21: 1.2 | D21: =(C21)*(1+$T$2)^(D$8-C$8) -> 1.2 | E21: =(D21)*(1+$T$2)^(E$8-D$8) -> 1.2 | F21: =(E21)*(1+$T$2)^(F$8-E$8) -> 1.2 | G21: =(F21)*(1+$T$2)^(G$8-F$8) -> 1.2 | H21: =(G21)*(1+$T$2)^(H$8-G$8) -> 1.2 | I21: =(H21)*(1+$T$2)^(I$8-H$8) -> 1.2 | K21: yearly | L21: Driver | M21: NL | N21: 0 | O21: NA | P21: NA | Q21: NA
A22: Ethylene production - Chemical Industry | B22: [Mton_Ey] | C22: =2.4+EnergyBalance!$CS$71*Activities!$C$26+EnergyBalance!$CS$72*Activities!$C$27+EnergyBalance!$CS$73*Activities!$C$28+EnergyBalance!$CS$80*Activities!$C$31+EnergyBalance!$CS$87*Activities!$C$33+EnergyBalance!$CS$87*EnergyBalance!$CZ$88*EnergyBalance!$DA$79*Activities!$C$32 -> 0.4003093 | D22: =(C22)*(1+$T$2)^(D$8-C$8) -> 0.4003093 | E22: =(D22)*(1+$T$2)^(E$8-D$8) -> 0.4003093 | F22: =(E22)*(1+$T$2)^(F$8-E$8) -> 0.4003093 | G22: =(F22)*(1+$T$2)^(G$8-F$8) -> 0.4003093 | H22: =(G22)*(1+$T$2)^(H$8-G$8) -> 0.4003093 | I22: =(H22)*(1+$T$2)^(I$8-H$8) -> 0.4003093 | K22: yearly | L22: Driver | M22: NL | N22: 0 | O22: NA | P22: NA | Q22: NA
A23: Propylene production - Chemical Industry | B23: [Mton_Py] | C23: =2.4*(0.136/0.303)-C29*1.02+0.5 -> 0.96522772 | D23: =(C23)*(1+$T$2)^(D$8-C$8) -> 0.96522772 | E23: =(D23)*(1+$T$2)^(E$8-D$8) -> 0.96522772 | F23: =(E23)*(1+$T$2)^(F$8-E$8) -> 0.96522772 | G23: =(F23)*(1+$T$2)^(G$8-F$8) -> 0.96522772 | H23: =(G23)*(1+$T$2)^(H$8-G$8) -> 0.96522772 | I23: =(H23)*(1+$T$2)^(I$8-H$8) -> 0.96522772 | K23: yearly | L23: Driver | M23: NL | N23: 0 | O23: NA | P23: NA | Q23: NA
A24: Butadiene production - Chemical Industry | B24: [Mton_Butadiene] | C24: =0.43/3*2.4 -> 0.344 | D24: =(C24)*(1+$T$2)^(D$8-C$8) -> 0.344 | E24: =(D24)*(1+$T$2)^(E$8-D$8) -> 0.344 | F24: =(E24)*(1+$T$2)^(F$8-E$8) -> 0.344 | G24: =(F24)*(1+$T$2)^(G$8-F$8) -> 0.344 | H24: =(G24)*(1+$T$2)^(H$8-G$8) -> 0.344 | I24: =(H24)*(1+$T$2)^(I$8-H$8) -> 0.344 | K24: yearly | L24: Driver | M24: NL | N24: 0 | O24: NA | P24: NA | Q24: NA
A25: BTX aromatics production - Chemical Industry | B25: [Mton_BTX] | C25: 3 | D25: =(C25)*(1+$T$2)^(D$8-C$8) -> 3 | E25: =(D25)*(1+$T$2)^(E$8-D$8) -> 3 | F25: =(E25)*(1+$T$2)^(F$8-E$8) -> 3 | G25: =(F25)*(1+$T$2)^(G$8-F$8) -> 3 | H25: =(G25)*(1+$T$2)^(H$8-G$8) -> 3 | I25: =(H25)*(1+$T$2)^(I$8-H$8) -> 3 | K25: yearly | L25: Driver | M25: NL | N25: 0 | O25: NA | P25: NA | Q25: NA
A26: LDPE production - Chemical Industry | B26: [Mton_LDPE] | C26: =0.73/3*2.4 -> 0.584 | D26: =(C26)*(1+$T$2)^(D$8-C$8) -> 0.584 | E26: =(D26)*(1+$T$2)^(E$8-D$8) -> 0.584 | F26: =(E26)*(1+$T$2)^(F$8-E$8) -> 0.584 | G26: =(F26)*(1+$T$2)^(G$8-F$8) -> 0.584 | H26: =(G26)*(1+$T$2)^(H$8-G$8) -> 0.584 | I26: =(H26)*(1+$T$2)^(I$8-H$8) -> 0.584 | K26: yearly | L26: Driver | M26: NL | N26: 0 | O26: NA | P26: NA | Q26: NA
A27: LLDPE production - Chemical Industry | B27: [Mton_LLDPE] | C27: =0.8/3*2.4 -> 0.64 | D27: =(C27)*(1+$T$2)^(D$8-C$8) -> 0.64 | E27: =(D27)*(1+$T$2)^(E$8-D$8) -> 0.64 | F27: =(E27)*(1+$T$2)^(F$8-E$8) -> 0.64 | G27: =(F27)*(1+$T$2)^(G$8-F$8) -> 0.64 | H27: =(G27)*(1+$T$2)^(H$8-G$8) -> 0.64 | I27: =(H27)*(1+$T$2)^(I$8-H$8) -> 0.64 | K27: yearly | L27: Driver | M27: NL | N27: 0 | O27: NA | P27: NA | Q27: NA
A28: HDPE production - Chemical Industry | B28: [Mton_HDPE] | C28: =0.31/3*2.4 -> 0.248 | D28: =(C28)*(1+$T$2)^(D$8-C$8) -> 0.248 | E28: =(D28)*(1+$T$2)^(E$8-D$8) -> 0.248 | F28: =(E28)*(1+$T$2)^(F$8-E$8) -> 0.248 | G28: =(F28)*(1+$T$2)^(G$8-F$8) -> 0.248 | H28: =(G28)*(1+$T$2)^(H$8-G$8) -> 0.248 | I28: =(H28)*(1+$T$2)^(I$8-H$8) -> 0.248 | K28: yearly | L28: Driver | M28: NL | N28: 0 | O28: NA | P28: NA | Q28: NA
A29: Polypropylene production - Chemical Industry | B29: [Mton_PP] | C29: =0.75/3*2.4 -> 0.6 | D29: =(C29)*(1+$T$2)^(D$8-C$8) -> 0.6 | E29: =(D29)*(1+$T$2)^(E$8-D$8) -> 0.6 | F29: =(E29)*(1+$T$2)^(F$8-E$8) -> 0.6 | G29: =(F29)*(1+$T$2)^(G$8-F$8) -> 0.6 | H29: =(G29)*(1+$T$2)^(H$8-G$8) -> 0.6 | I29: =(H29)*(1+$T$2)^(I$8-H$8) -> 0.6 | K29: yearly | L29: Driver | M29: NL | N29: 0 | O29: NA | P29: NA | Q29: NA
A30: PTA production - Chemical Industry | B30: [Mton_PTA] | C30: =0.342/3*2.4 -> 0.2736 | D30: =(C30)*(1+$T$2)^(D$8-C$8) -> 0.2736 | E30: =(D30)*(1+$T$2)^(E$8-D$8) -> 0.2736 | F30: =(E30)*(1+$T$2)^(F$8-E$8) -> 0.2736 | G30: =(F30)*(1+$T$2)^(G$8-F$8) -> 0.2736 | H30: =(G30)*(1+$T$2)^(H$8-G$8) -> 0.2736 | I30: =(H30)*(1+$T$2)^(I$8-H$8) -> 0.2736 | K30: yearly | L30: Driver | M30: NL | N30: 0 | O30: NA | P30: NA | Q30: NA
A31: PVC production - Chemical Industry | B31: [Mton_PVC] | C31: =0.75/3*2.4 -> 0.6 | D31: =(C31)*(1+$T$2)^(D$8-C$8) -> 0.6 | E31: =(D31)*(1+$T$2)^(E$8-D$8) -> 0.6 | F31: =(E31)*(1+$T$2)^(F$8-E$8) -> 0.6 | G31: =(F31)*(1+$T$2)^(G$8-F$8) -> 0.6 | H31: =(G31)*(1+$T$2)^(H$8-G$8) -> 0.6 | I31: =(H31)*(1+$T$2)^(I$8-H$8) -> 0.6 | K31: yearly | L31: Driver | M31: NL | N31: 0 | O31: NA | P31: NA | Q31: NA
A32: Polyester production - Chemical Industry | B32: [Mton_material] | C32: =0.426/3*2.4 -> 0.3408 | D32: =(C32)*(1+$T$2)^(D$8-C$8) -> 0.3408 | E32: =(D32)*(1+$T$2)^(E$8-D$8) -> 0.3408 | F32: =(E32)*(1+$T$2)^(F$8-E$8) -> 0.3408 | G32: =(F32)*(1+$T$2)^(G$8-F$8) -> 0.3408 | H32: =(G32)*(1+$T$2)^(H$8-G$8) -> 0.3408 | I32: =(H32)*(1+$T$2)^(I$8-H$8) -> 0.3408 | K32: yearly | L32: Driver | M32: NL | N32: 0 | O32: NA | P32: NA | Q32: NA
A33: Ethylene oxide production - Chemical Industry | B33: [Mton_EO] | C33: =0.183/3*2.4 -> 0.1464 | D33: =(C33)*(1+$T$2)^(D$8-C$8) -> 0.1464 | E33: =(D33)*(1+$T$2)^(E$8-D$8) -> 0.1464 | F33: =(E33)*(1+$T$2)^(F$8-E$8) -> 0.1464 | G33: =(F33)*(1+$T$2)^(G$8-F$8) -> 0.1464 | H33: =(G33)*(1+$T$2)^(H$8-G$8) -> 0.1464 | I33: =(H33)*(1+$T$2)^(I$8-H$8) -> 0.1464 | K33: yearly | L33: Driver | M33: NL | N33: 0 | O33: NA | P33: NA | Q33: NA
A34: Chlorine production - Chemical Industry | B34: [Mton_CL2] | C34: 1 | D34: =(C34)*(1+$T$2)^(D$8-C$8) -> 1 | E34: =(D34)*(1+$T$2)^(E$8-D$8) -> 1 | F34: =(E34)*(1+$T$2)^(F$8-E$8) -> 1 | G34: =(F34)*(1+$T$2)^(G$8-F$8) -> 1 | H34: =(G34)*(1+$T$2)^(H$8-G$8) -> 1 | I34: =(H34)*(1+$T$2)^(I$8-H$8) -> 1 | K34: yearly | L34: Driver | M34: NL | N34: 0 | O34: NA | P34: NA | Q34: NA
A35: Other ETS chemicals - Chemical Industry | B35: [Idx_2020] | C35: 1 | D35: =(C35)*(1+$T$2)^(D$8-C$8) -> 1 | E35: =(D35)*(1+$T$2)^(E$8-D$8) -> 1 | F35: =(E35)*(1+$T$2)^(F$8-E$8) -> 1 | G35: =(F35)*(1+$T$2)^(G$8-F$8) -> 1 | H35: =(G35)*(1+$T$2)^(H$8-G$8) -> 1 | I35: =(H35)*(1+$T$2)^(I$8-H$8) -> 1 | K35: yearly | L35: Driver | M35: NL | N35: 0 | O35: NA | P35: NA | Q35: NA
A36: Glass production - ETS Industry | B36: [Mton_Glass] | C36: 0.92 | D36: =(C36)*(1+$T$2)^(D$8-C$8) -> 0.92 | E36: =(D36)*(1+$T$2)^(E$8-D$8) -> 0.92 | F36: =(E36)*(1+$T$2)^(F$8-E$8) -> 0.92 | G36: =(F36)*(1+$T$2)^(G$8-F$8) -> 0.92 | H36: =(G36)*(1+$T$2)^(H$8-G$8) -> 0.92 | I36: =(H36)*(1+$T$2)^(I$8-H$8) -> 0.92 | K36: yearly | L36: Driver | M36: NL | N36: 0 | O36: NA | P36: NA | Q36: NA
A37: Ceramics production -ETS Industry | B37: [Mton_Ceramics] | C37: =(2.39+2.94)/2 -> 2.665 | D37: =(C37)*(1+$T$2)^(D$8-C$8) -> 2.665 | E37: =(D37)*(1+$T$2)^(E$8-D$8) -> 2.665 | F37: =(E37)*(1+$T$2)^(F$8-E$8) -> 2.665 | G37: =(F37)*(1+$T$2)^(G$8-F$8) -> 2.665 | H37: =(G37)*(1+$T$2)^(H$8-G$8) -> 2.665 | I37: =(H37)*(1+$T$2)^(I$8-H$8) -> 2.665 | K37: yearly | L37: Driver | M37: NL | N37: 0 | O37: NA | P37: NA | Q37: NA
A38: Paper production - ETS Industry | B38: [Mton_Paper] | C38: 1.015 | D38: =(C38)*(1+$T$2)^(D$8-C$8) -> 1.015 | E38: =(D38)*(1+$T$2)^(E$8-D$8) -> 1.015 | F38: =(E38)*(1+$T$2)^(F$8-E$8) -> 1.015 | G38: =(F38)*(1+$T$2)^(G$8-F$8) -> 1.015 | H38: =(G38)*(1+$T$2)^(H$8-G$8) -> 1.015 | I38: =(H38)*(1+$T$2)^(I$8-H$8) -> 1.015 | K38: yearly | L38: Driver | M38: NL | N38: 0 | O38: NA | P38: NA | Q38: NA
A39: Board production - ETS Industry | B39: [Mton_board] | C39: 1.855 | D39: =(C39)*(1+$T$2)^(D$8-C$8) -> 1.855 | E39: =(D39)*(1+$T$2)^(E$8-D$8) -> 1.855 | F39: =(E39)*(1+$T$2)^(F$8-E$8) -> 1.855 | G39: =(F39)*(1+$T$2)^(G$8-F$8) -> 1.855 | H39: =(G39)*(1+$T$2)^(H$8-G$8) -> 1.855 | I39: =(H39)*(1+$T$2)^(I$8-H$8) -> 1.855 | K39: yearly | L39: Driver | M39: NL | N39: 0 | O39: NA | P39: NA | Q39: NA
A40: Food production - non-ETS Industry | B40: [Idx_2020] | C40: 1 | D40: =(C40)*(1+$T$2)^(D$8-C$8) -> 1 | E40: =(D40)*(1+$T$2)^(E$8-D$8) -> 1 | F40: =(E40)*(1+$T$2)^(F$8-E$8) -> 1 | G40: =(F40)*(1+$T$2)^(G$8-F$8) -> 1 | H40: =(G40)*(1+$T$2)^(H$8-G$8) -> 1 | I40: =(H40)*(1+$T$2)^(I$8-H$8) -> 1 | K40: yearly | L40: Driver | M40: NL | N40: 0 | O40: NA | P40: NA | Q40: NA
...

Sheet Technologies
A2: Tech. Specifics | I2: Cost data | AI2: Operation data | AM2: CHP flexibility data | AS2: Asymetric flexibility | AV2: Hydro Reservoirs | AY2: Flexibility data | BH2: Network buffers | BO2: Planned decommissioning | BU2: Minimum stock in a year | CB2: Maximum stock in a year | CI2: Minimum use in a year | CP2: Maximum use in a year | CW2: No new investments | DD2: No economic/early decommissioning | DK2: Data source | DL2: Reference Volume of the main activity
A3: Tech_ID | B3: Policy Sectors | C3: Category | D3: Sector | E3: Sub-sector | F3: Main Activity | G3: Name | H3: UoC | I3: Investment | J3: Investment | K3: Investment | L3: Investment | M3: Investment | N3: Investment | O3: Investment | P3: Salvage value | Q3: Fixed O&M | R3: Fixed O&M | S3: Fixed O&M | T3: Fixed O&M | U3: Fixed O&M | V3: Fixed O&M | W3: Fixed O&M | X3: Variable O&M | Y3: Variable O&M | Z3: Variable O&M | AA3: Variable O&M | AB3: Variable O&M | AC3: Variable O&M | AD3: Variable O&M | AE3: WACC | AF3: Const. Time | AG3: Ec. Lifetime | AH3: Tech. Lifetime | AI3: Cap2Act | AJ3: Type of process | AK3: Type of profile | AL3: Ramping constraint | AM3: CHP product | AN3: CHP fuel | AO3: CHP η | AP3: CHP heat balance range | AQ3: CHP deviation in USE tolerance | AR3: CHP deviation in P/H RATIO tolerance | AS3: Shedding capacity | AT3: Shedding volume | AU3: Range for demand curtailing | AV3: Pump to head ratio | AW3: Reservoir capacity | AX3: Pumping losses | AY3: Form of Flexibility | AZ3: Benefited activity | BA3: Flexible capacity | BB3: Storage capacity | BC3: Shifting range | BD3: Losses | BE3: Non-negotiable load | BF3: Average journey duration | BG3: Average speed | BH3: Benefited activity | BI3: Upward capacity | BJ3: Downward capacity | BK3: Buffer capacity | BL3: Current installed capacity needed | BM3: Maximum technology deployment | BN3: Current Installed Capacity | CB3: 0 | CC3: 0 | CD3: 0.1 | CE3: 0.2 | CF3: 0.5 | CG3: 1 | CH3: 1 | CW3: 1 = no new investments allowed in this year | DD3: 1 = no early decommissioning allowed in this year | DL3: (also works as an auxiliary)
I4: =Parameters!$B$13 -> 2022 | J4: 2025 | K4: 2030 | L4: 2035 | M4: 2040 | N4: 2045 | O4: 2050 | P4: % of CAPEX | Q4: =Parameters!$B$13 -> 2022 | R4: 2025 | S4: 2030 | T4: 2035 | U4: 2040 | V4: 2045 | W4: 2050 | X4: =Parameters!$B$13 -> 2022 | Y4: 2025 | Z4: 2030 | AA4: 2035 | AB4: 2040 | AC4: 2045 | AD4: 2050 | AP4: (h,d,w) | AQ4: (only for CHP) | AR4: (only for CHP) | AT4: (if range is more than 1 hour) | AV4: (zero if not PS) | AW4: (hours of discharge) | BB4: (hours of charge) | BK4: (in relation to discharge) | BL4: (not in the model) | BO4: 1 | BP4: 2 | BQ4: 3 | BR4: 4 | BS4: 5 | BT4: 6 | CB4: 0 | CC4: 0.5 | CD4: 1 | CE4: 1 | CF4: 1 | CG4: 1 | CH4: 1 | CZ4: [y/n] | DG4: [y/n] | DO4: (no AIMMS)
AJ5: (mandatory) | AK5: (mandatory) | AL5: (only for Hourly dispatch) | BB5: (only if storage is present) | BF5: (only for flexible electric transport) | BG5: (only for flexible electric transport) | BN5: =Parameters!$B$13 -> 2022 | BO5: 2025 | BP5: 2030 | BQ5: 2035 | BR5: 2040 | BS5: 2045 | BT5: 2050 | BU5: =Parameters!$B$13 -> 2022 | BV5: 2025 | BW5: 2030 | BX5: 2035 | BY5: 2040 | BZ5: 2045 | CA5: 2050 | CB5: =Parameters!$B$13 -> 2022 | CC5: 2025 | CD5: 2030 | CE5: 2035 | CF5: 2040 | CG5: 2045 | CH5: 2050 | CI5: =Parameters!$B$13 -> 2022 | CJ5: 2025 | CK5: 2030 | CL5: 2035 | CM5: 2040 | CN5: 2045 | CO5: 2050 | CP5: =Parameters!$B$13 -> 2022 | CQ5: 2025 | CR5: 2030 | CS5: 2035 | CT5: 2040 | CU5: 2045 | CV5: 2050 | CW5: =Parameters!$B$13 -> 2022 | CX5: 2025 | CY5: 2030 | CZ5: 2035 | DA5: 2040 | DB5: 2045 | DC5: 2050 | DD5: =Parameters!$B$13 -> 2022 | DE5: 2025 | DF5: 2030 | DG5: 2035 | DH5: 2040 | DI5: 2045 | DJ5: 2050
I6: [M€/UoC] | J6: [M€/UoC] | K6: [M€/UoC] | L6: [M€/UoC] | M6: [M€/UoC] | N6: [M€/UoC] | O6: [M€/UoC] | P6: [%] | Q6: [M€/UoC-y] | R6: [M€/UoC-y] | S6: [M€/UoC-y] | T6: [M€/UoC-y] | U6: [M€/UoC-y] | V6: [M€/UoC-y] | W6: [M€/UoC-y] | X6: [M€/UoA] | Y6: [M€/UoA] | Z6: [M€/UoA] | AA6: [M€/UoA] | AB6: [M€/UoA] | AC6: [M€/UoA] | AD6: [M€/UoA] | AE6: [1/y] | AF6: [y] | AG6: [y] | AH6: [y] | AI6: [UoA/UoC-y] | AJ6: [type] | AK6: [type] | AL6: [%] | AM6: [activity] | AN6: [activity] | AO6: [%] | AP6: [UoR] | AQ6: [%] | AR6: [%] | AS6: [%] | AT6: [%] | AU6: [UoR] | AV6: [%] | AW6: [h] | AX6: [%] | AY6: [type] | AZ6: [activity] | BA6: [%] | BB6: [h] | BC6: [UoR] | BD6: [%] | BE6: [%] | BF6: [h] | BG6: [UoA/UoC-h] | BH6: [activity] | BI6: [PJ/UoC-d] | BJ6: [PJ/UoC-d] | BK6: [d] | BL6: [y/n] | BM6: [UoC/5y] | BN6: [UoC] | BO6: [UoC] | BP6: [UoC] | BQ6: [UoC] | BR6: [UoC] | BS6: [UoC] | BT6: [UoC] | BU6: [UoC] | BV6: [UoC] | BW6: [UoC] | BX6: [UoC] | BY6: [UoC] | BZ6: [UoC] | CA6: [UoC] | CB6: [UoC] | CC6: [UoC] | CD6: [UoC] | CE6: [UoC] | CF6: [UoC] | CG6: [UoC] | CH6: [UoC] | CI6: [UoA] | CJ6: [UoA] | CK6: [UoA] | CL6: [UoA] | CM6: [UoA] | CN6: [UoA] | CO6: [UoA] | CP6: [UoA] | CQ6: [UoA] | CR6: [UoA] | CS6: [UoA] | CT6: [UoA] | CU6: [UoA] | CV6: [UoA] | CW6: [y/n] | CX6: [y/n] | CY6: [y/n] | CZ6: [y/n] | DA6: [y/n] | DB6: [y/n] | DC6: [y/n] | DD6: [y/n] | DE6: [y/n] | DF6: [y/n] | DG6: [y/n] | DH6: [y/n] | DI6: [y/n] | DJ6: [y/n] | DK6: [ref No.] | DL6: =Parameters!$B$13 -> 2022 | DM6: 2025 | DN6: 2030 | DO6: 2035 | DP6: 2040 | DQ6: 2045 | DR6: 2050
A7: Res01_01 | B7: Gebouwde omgeving | C7: Final | D7: Residential | E7: Appliances | F7: Electricity demand - Residential | G7: Dummy standard electricity consumption - Residential | H7: [PJ/y] | I7: 0 | J7: 0 | K7: 0 | L7: 0 | M7: 0 | N7: 0 | O7: 0 | P7: 0 | Q7: 0 | R7: 0 | S7: 0 | T7: 0 | U7: 0 | V7: 0 | W7: 0 | X7: 0 | Y7: 0 | Z7: 0 | AA7: 0 | AB7: 0 | AC7: 0 | AD7: 0 | AE7: 0.08 | AF7: 0 | AG7: 1 | AH7: 1 | AI7: 1 | AJ7: Operation | AK7: Standard Load | AY7: none | BN7: =DL7 -> 80.1 | BO7: 0 | BP7: 0 | BQ7: 0 | BR7: 0 | BS7: 0 | BT7: 0 | BU7: =IF(BL7=1,BN7,0) -> 0 | CB7: =DL7 -> 80.1 | CC7: =DM7 -> 83.547169 | CD7: =DN7 -> 85.414196 | CE7: =DO7 -> 86.416015 | CF7: =DP7 -> 86.807635 | CG7: =DQ7 -> 86.712007 | CH7: =DR7 -> 86.329494 | DK7: [1],[12] | DL7: =VLOOKUP($F7,Activities!$A$9:$I$180,3,FALSE)/$AI7 -> 80.1 | DM7: =VLOOKUP($F7,Activities!$A$9:$I$180,4,FALSE)/$AI7 -> 83.547169 | DN7: =VLOOKUP($F7,Activities!$A$9:$I$180,5,FALSE)/$AI7 -> 85.414196 | DO7: =VLOOKUP($F7,Activities!$A$9:$I$180,6,FALSE)/$AI7 -> 86.416015 | DP7: =VLOOKUP($F7,Activities!$A$9:$I$180,7,FALSE)/$AI7 -> 86.807635 | DQ7: =VLOOKUP($F7,Activities!$A$9:$I$180,8,FALSE)/$AI7 -> 86.712007 | DR7: =VLOOKUP($F7,Activities!$A$9:$I$180,9,FALSE)/$AI7 -> 86.329494
A8: Res01_02 | B8: Gebouwde omgeving | C8: Final | D8: Residential | E8: Appliances | F8: Electricity demand - Residential | G8: Flexible standard electricity consumption - Residential | H8: [PJ/y] | I8: 0.5 | J8: 0.5 | K8: 0.5 | L8: 0.3 | M8: 0.1 | N8: 0 | O8: 0 | P8: 0 | Q8: 0 | R8: 0 | S8: 0 | T8: 0 | U8: 0 | V8: 0 | W8: 0 | X8: 0 | Y8: 0 | Z8: 0 | AA8: 0 | AB8: 0 | AC8: 0 | AD8: 0 | AE8: 0.08 | AF8: 0 | AG8: 15 | AH8: 15 | AI8: 1 | AJ8: Operation | AK8: Standard Load | AY8: DR shifting | AZ8: Electricity NL - LV | BA8: 1 | BC8: 1 day [d] | BD8: 0.02 | BE8: 0.8 | BN8: 0.5 | BQ8: 0.5 | BU8: =IF(BL8=1,BN8,0) -> 0 | CB8: 0.5 | CC8: 1 | CD8: 2 | CE8: 4 | CF8: 8 | CG8: 20 | CH8: 32 | DK8: [1],[12] | DL8: =VLOOKUP($F8,Activities!$A$9:$I$180,3,FALSE)/$AI8 -> 80.1 | DM8: =VLOOKUP($F8,Activities!$A$9:$I$180,4,FALSE)/$AI8 -> 83.547169 | DN8: =VLOOKUP($F8,Activities!$A$9:$I$180,5,FALSE)/$AI8 -> 85.414196 | DO8: =VLOOKUP($F8,Activities!$A$9:$I$180,6,FALSE)/$AI8 -> 86.416015 | DP8: =VLOOKUP($F8,Activities!$A$9:$I$180,7,FALSE)/$AI8 -> 86.807635 | DQ8: =VLOOKUP($F8,Activities!$A$9:$I$180,8,FALSE)/$AI8 -> 86.712007 | DR8: =VLOOKUP($F8,Activities!$A$9:$I$180,9,FALSE)/$AI8 -> 86.329494
A9: Res02_01 | B9: Gebouwde omgeving | C9: Final | D9: Residential | E9: Flats | F9: Houses - Residential Flats | G9: House with insulation GFE - Residential Flats | H9: [khouses/y] | I9: 0 | J9: 0 | K9: 0 | L9: 0 | M9: 0 | N9: 0 | O9: 0 | P9: 0 | Q9: 0 | R9: 0 | S9: 0 | T9: 0 | U9: 0 | V9: 0 | W9: 0 | X9: 0 | Y9: 0 | Z9: 0 | AA9: 0 | AB9: 0 | AC9: 0 | AD9: 0 | AE9: 0.08 | AF9: 0 | AG9: 40 | AH9: 40 | AI9: 1 | AJ9: Operation | AK9: Built Environment | AY9: none | BL9: 1 | BN9: =IF(SUM(CB9:CB9)<DL9,CB9,DL9-SUM(CB9:CB9)) -> 1000 | BT9: 0 | BU9: =IF(BL9=1,BN9,0) -> 1000 | CB9: 1000 | CC9: =DM9 -> 3041.4924 | CD9: =DN9 -> 3109.4606 | CE9: =DO9 -> 3145.9313 | CF9: =DP9 -> 3160.1881 | CG9: =DQ9 -> 3156.7068 | CH9: =DR9 -> 3142.7816 | CX9: 1 | CY9: 1 | CZ9: 1 | DA9: 1 | DB9: 1 | DC9: 1 | DK9: [1],[12] | DL9: =VLOOKUP($F9,Activities!$A$9:$I$180,3,FALSE)/$AI9 -> 2916 | DM9: =VLOOKUP($F9,Activities!$A$9:$I$180,4,FALSE)/$AI9 -> 3041.4924 | DN9: =VLOOKUP($F9,Activities!$A$9:$I$180,5,FALSE)/$AI9 -> 3109.4606 | DO9: =VLOOKUP($F9,Activities!$A$9:$I$180,6,FALSE)/$AI9 -> 3145.9313 | DP9: =VLOOKUP($F9,Activities!$A$9:$I$180,7,FALSE)/$AI9 -> 3160.1881 | DQ9: =VLOOKUP($F9,Activities!$A$9:$I$180,8,FALSE)/$AI9 -> 3156.7068 | DR9: =VLOOKUP($F9,Activities!$A$9:$I$180,9,FALSE)/$AI9 -> 3142.7816
A10: Res02_02 | B10: Gebouwde omgeving | C10: Final | D10: Residential | E10: Flats | F10: Houses - Residential Flats | G10: House with insulation DC - Residential Flats | H10: [khouses/y] | I10: 2.37 | J10: 2.37 | K10: 2.37 | L10: 0 | M10: 0 | N10: 0 | O10: 0 | P10: 0 | Q10: 0 | R10: 0 | S10: 0 | T10: 0 | U10: 0 | V10: 0 | W10: 0 | X10: 0 | Y10: 0 | Z10: 0 | AA10: 0 | AB10: 0 | AC10: 0 | AD10: 0 | AE10: 0.08 | AF10: 0 | AG10: 40 | AH10: 40 | AI10: 1 | AJ10: Operation | AK10: Built Environment | AY10: none | BL10: 1 | BN10: =IF(SUM(CB9:CB10)<DL10,CB10,DL10-SUM(CB9:CB9)) -> 1150 | BU10: 1050 | CB10: 1150 | CC10: =DM10 -> 3041.4924 | CD10: =DN10 -> 3109.4606 | CE10: =DO10 -> 3145.9313 | CF10: =DP10 -> 3160.1881 | CG10: =DQ10 -> 3156.7068 | CH10: =DR10 -> 3142.7816 | CY10: 1 | CZ10: 1 | DA10: 1 | DB10: 1 | DC10: 1 | DK10: [1],[12] | DL10: =VLOOKUP($F10,Activities!$A$9:$I$180,3,FALSE)/$AI10 -> 2916 | DM10: =VLOOKUP($F10,Activities!$A$9:$I$180,4,FALSE)/$AI10 -> 3041.4924 | DN10: =VLOOKUP($F10,Activities!$A$9:$I$180,5,FALSE)/$AI10 -> 3109.4606 | DO10: =VLOOKUP($F10,Activities!$A$9:$I$180,6,FALSE)/$AI10 -> 3145.9313 | DP10: =VLOOKUP($F10,Activities!$A$9:$I$180,7,FALSE)/$AI10 -> 3160.1881 | DQ10: =VLOOKUP($F10,Activities!$A$9:$I$180,8,FALSE)/$AI10 -> 3156.7068 | DR10: =VLOOKUP($F10,Activities!$A$9:$I$180,9,FALSE)/$AI10 -> 3142.7816
A11: Res02_03 | B11: Gebouwde omgeving | C11: Final | D11: Residential | E11: Flats | F11: Houses - Residential Flats | G11: House with insulation B - Residential Flats | H11: [khouses/y] | I11: 8.2 | J11: 8.2 | K11: 8.2 | L11: 5.8 | M11: 5.8 | N11: 0 | O11: 0 | P11: 0 | Q11: 0 | R11: 0 | S11: 0 | T11: 0 | U11: 0 | V11: 0 | W11: 0 | X11: 0 | Y11: 0 | Z11: 0 | AA11: 0 | AB11: 0 | AC11: 0 | AD11: 0 | AE11: 0.08 | AF11: 0 | AG11: 40 | AH11: 40 | AI11: 1 | AJ11: Operation | AK11: Built Environment | AY11: none | BL11: 1 | BN11: =IF(SUM(CB9:CB11)<DL11,CB11,DL11-SUM(CB9:CB10)) -> 500 | BU11: =IF(BL11=1,BN11,0) -> 500 | CB11: 500 | CC11: =DM11 -> 3041.4924 | CD11: =DN11 -> 3109.4606 | CE11: =DO11 -> 3145.9313 | CF11: =DP11 -> 3160.1881 | CG11: =DQ11 -> 3156.7068 | CH11: =DR11 -> 3142.7816 | CZ11: 1 | DA11: 1 | DB11: 1 | DC11: 1 | DK11: [1],[12] | DL11: =VLOOKUP($F11,Activities!$A$9:$I$180,3,FALSE)/$AI11 -> 2916 | DM11: =VLOOKUP($F11,Activities!$A$9:$I$180,4,FALSE)/$AI11 -> 3041.4924 | DN11: =VLOOKUP($F11,Activities!$A$9:$I$180,5,FALSE)/$AI11 -> 3109.4606 | DO11: =VLOOKUP($F11,Activities!$A$9:$I$180,6,FALSE)/$AI11 -> 3145.9313 | DP11: =VLOOKUP($F11,Activities!$A$9:$I$180,7,FALSE)/$AI11 -> 3160.1881 | DQ11: =VLOOKUP($F11,Activities!$A$9:$I$180,8,FALSE)/$AI11 -> 3156.7068 | DR11: =VLOOKUP($F11,Activities!$A$9:$I$180,9,FALSE)/$AI11 -> 3142.7816
A12: Res02_04 | B12: Gebouwde omgeving | C12: Final | D12: Residential | E12: Flats | F12: Houses - Residential Flats | G12: House with insulation A - Residential Flats | H12: [khouses/y] | I12: 10.37 | J12: 10.11 | K12: 9.85 | L12: 7.2 | M12: 7.1 | N12: 1.3 | O12: 1.3 | P12: 0 | Q12: 0 | R12: 0 | S12: 0 | T12: 0 | U12: 0 | V12: 0 | W12: 0 | X12: 0 | Y12: 0 | Z12: 0 | AA12: 0 | AB12: 0 | AC12: 0 | AD12: 0 | AE12: 0.08 | AF12: 0 | AG12: 40 | AH12: 40 | AI12: 1 | AJ12: Operation | AK12: Built Environment | AY12: none | BN12: =IF(SUM(CB9:CB12)<DL12,CB12,DL12-SUM(CB9:CB11)) -> 250 | BU12: =IF(BL12=1,BN12,0) -> 0 | CB12: 250 | CC12: =DM12 -> 3041.4924 | CD12: =DN12 -> 3109.4606 | CE12: =DO12 -> 3145.9313 | CF12: =DP12 -> 3160.1881 | CG12: =DQ12 -> 3156.7068 | CH12: =DR12 -> 3142.7816 | DF12: 1 | DG12: 1 | DH12: 1 | DI12: 1 | DJ12: 1 | DK12: [1],[12] | DL12: =VLOOKUP($F12,Activities!$A$9:$I$180,3,FALSE)/$AI12 -> 2916 | DM12: =VLOOKUP($F12,Activities!$A$9:$I$180,4,FALSE)/$AI12 -> 3041.4924 | DN12: =VLOOKUP($F12,Activities!$A$9:$I$180,5,FALSE)/$AI12 -> 3109.4606 | DO12: =VLOOKUP($F12,Activities!$A$9:$I$180,6,FALSE)/$AI12 -> 3145.9313 | DP12: =VLOOKUP($F12,Activities!$A$9:$I$180,7,FALSE)/$AI12 -> 3160.1881 | DQ12: =VLOOKUP($F12,Activities!$A$9:$I$180,8,FALSE)/$AI12 -> 3156.7068 | DR12: =VLOOKUP($F12,Activities!$A$9:$I$180,9,FALSE)/$AI12 -> 3142.7816
A13: Res02_05 | B13: Gebouwde omgeving | C13: Final | D13: Residential | E13: Flats | F13: Houses - Residential Flats | G13: House with insulation A+ - Residential Flats | H13: [khouses/y] | I13: 12.26 | J13: 11.65 | K13: 11.04 | L13: 8.1 | M13: 7.5 | N13: 1.7 | O13: 1.5 | P13: 0 | Q13: 0 | R13: 0 | S13: 0 | T13: 0 | U13: 0 | V13: 0 | W13: 0 | X13: 0 | Y13: 0 | Z13: 0 | AA13: 0 | AB13: 0 | AC13: 0 | AD13: 0 | AE13: 0.08 | AF13: 0 | AG13: 40 | AH13: 40 | AI13: 1 | AJ13: Operation | AK13: Built Environment | AY13: none | BN13: =IF(SUM(CB9:CB13)<DL13,CB13,DL13-SUM(CB9:CB12)) -> 16 | BU13: =IF(BL13=1,BN13,0) -> 0 | CB13: 100 | CC13: =DM13 -> 3041.4924 | CD13: =DN13 -> 3109.4606 | CE13: =DO13 -> 3145.9313 | CF13: =DP13 -> 3160.1881 | CG13: =DQ13 -> 3156.7068 | CH13: =DR13 -> 3142.7816 | DF13: 1 | DG13: 1 | DH13: 1 | DI13: 1 | DJ13: 1 | DK13: [1],[9],[12] | DL13: =VLOOKUP($F13,Activities!$A$9:$I$180,3,FALSE)/$AI13 -> 2916 | DM13: =VLOOKUP($F13,Activities!$A$9:$I$180,4,FALSE)/$AI13 -> 3041.4924 | DN13: =VLOOKUP($F13,Activities!$A$9:$I$180,5,FALSE)/$AI13 -> 3109.4606 | DO13: =VLOOKUP($F13,Activities!$A$9:$I$180,6,FALSE)/$AI13 -> 3145.9313 | DP13: =VLOOKUP($F13,Activities!$A$9:$I$180,7,FALSE)/$AI13 -> 3160.1881 | DQ13: =VLOOKUP($F13,Activities!$A$9:$I$180,8,FALSE)/$AI13 -> 3156.7068 | DR13: =VLOOKUP($F13,Activities!$A$9:$I$180,9,FALSE)/$AI13 -> 3142.7816
A14: Res03_01 | B14: Gebouwde omgeving | C14: Final | D14: Residential | E14: Terrace | F14: Houses - Residential Terrace | G14: House with insulation GFE - Residential Terrace | H14: [khouses/y] | I14: 0 | J14: 0 | K14: 0 | L14: 0 | M14: 0 | N14: 0 | O14: 0 | P14: 0 | Q14: 0 | R14: 0 | S14: 0 | T14: 0 | U14: 0 | V14: 0 | W14: 0 | X14: 0 | Y14: 0 | Z14: 0 | AA14: 0 | AB14: 0 | AC14: 0 | AD14: 0 | AE14: 0.08 | AF14: 0 | AG14: 40 | AH14: 40 | AI14: 1 | AJ14: Operation | AK14: Built Environment | AY14: none | BL14: 1 | BN14: =IF(SUM(CB14:CB14)<DL14,CB14,MAX(DL14-SUM(CB14:CB14),0)) -> 2000 | BU14: 800 | CB14: 2000 | CC14: =DM14 -> 3525.4611 | CD14: =DN14 -> 3604.2445 | CE14: =DO14 -> 3646.5185 | CF14: =DP14 -> 3663.0438 | CG14: =DQ14 -> 3659.0085 | CH14: =DR14 -> 3642.8675 | CX14: 1 | CY14: 1 | CZ14: 1 | DA14: 1 | DB14: 1 | DC14: 1 | DK14: [1],[9],[12] | DL14: =VLOOKUP($F14,Activities!$A$9:$I$180,3,FALSE)/$AI14 -> 3380 | DM14: =VLOOKUP($F14,Activities!$A$9:$I$180,4,FALSE)/$AI14 -> 3525.4611 | DN14: =VLOOKUP($F14,Activities!$A$9:$I$180,5,FALSE)/$AI14 -> 3604.2445 | DO14: =VLOOKUP($F14,Activities!$A$9:$I$180,6,FALSE)/$AI14 -> 3646.5185 | DP14: =VLOOKUP($F14,Activities!$A$9:$I$180,7,FALSE)/$AI14 -> 3663.0438 | DQ14: =VLOOKUP($F14,Activities!$A$9:$I$180,8,FALSE)/$AI14 -> 3659.0085 | DR14: =VLOOKUP($F14,Activities!$A$9:$I$180,9,FALSE)/$AI14 -> 3642.8675
A15: Res03_02 | B15: Gebouwde omgeving | C15: Final | D15: Residential | E15: Terrace | F15: Houses - Residential Terrace | G15: House with insulation DC - Residential Terrace | H15: [khouses/y] | I15: 3.18 | J15: 3.18 | K15: 3.18 | L15: 0 | M15: 0 | N15: 0 | O15: 0 | P15: 0 | Q15: 0 | R15: 0 | S15: 0 | T15: 0 | U15: 0 | V15: 0 | W15: 0 | X15: 0 | Y15: 0 | Z15: 0 | AA15: 0 | AB15: 0 | AC15: 0 | AD15: 0 | AE15: 0.08 | AF15: 0 | AG15: 40 | AH15: 40 | AI15: 1 | AJ15: Operation | AK15: Built Environment | AY15: none | BL15: 1 | BN15: =IF(SUM(CB14:CB15)<DL15,CB15,MAX(DL15-SUM(CB14:CB14),0)) -> 1270 | BU15: 870 | CB15: 1270 | CC15: =DM15 -> 3525.4611 | CD15: =DN15 -> 3604.2445 | CE15: =DO15 -> 3646.5185 | CF15: =DP15 -> 3663.0438 | CG15: =DQ15 -> 3659.0085 | CH15: =DR15 -> 3642.8675 | CY15: 1 | CZ15: 1 | DA15: 1 | DB15: 1 | DC15: 1 | DK15: [1],[37],[38] | DL15: =VLOOKUP($F15,Activities!$A$9:$I$180,3,FALSE)/$AI15 -> 3380 | DM15: =VLOOKUP($F15,Activities!$A$9:$I$180,4,FALSE)/$AI15 -> 3525.4611 | DN15: =VLOOKUP($F15,Activities!$A$9:$I$180,5,FALSE)/$AI15 -> 3604.2445 | DO15: =VLOOKUP($F15,Activities!$A$9:$I$180,6,FALSE)/$AI15 -> 3646.5185 | DP15: =VLOOKUP($F15,Activities!$A$9:$I$180,7,FALSE)/$AI15 -> 3663.0438 | DQ15: =VLOOKUP($F15,Activities!$A$9:$I$180,8,FALSE)/$AI15 -> 3659.0085 | DR15: =VLOOKUP($F15,Activities!$A$9:$I$180,9,FALSE)/$AI15 -> 3642.8675
A16: Res03_03 | B16: Gebouwde omgeving | C16: Final | D16: Residential | E16: Terrace | F16: Houses - Residential Terrace | G16: House with insulation B - Residential Terrace | H16: [khouses/y] | I16: 9.71 | J16: 9.71 | K16: 9.71 | L16: 6.5 | M16: 6.5 | N16: 0 | O16: 0 | P16: 0 | Q16: 0 | R16: 0 | S16: 0 | T16: 0 | U16: 0 | V16: 0 | W16: 0 | X16: 0 | Y16: 0 | Z16: 0 | AA16: 0 | AB16: 0 | AC16: 0 | AD16: 0 | AE16: 0.08 | AF16: 0 | AG16: 40 | AH16: 40 | AI16: 1 | AJ16: Operation | AK16: Built Environment | AY16: none | BL16: 1 | BN16: =IF(SUM(CB14:CB16)<DL16,CB16,MAX(DL16-SUM(CB14:CB15),0)) -> 110 | BU16: 500 | CB16: 840 | CC16: =DM16 -> 3525.4611 | CD16: =DN16 -> 3604.2445 | CE16: =DO16 -> 3646.5185 | CF16: =DP16 -> 3663.0438 | CG16: =DQ16 -> 3659.0085 | CH16: =DR16 -> 3642.8675 | CZ16: 1 | DA16: 1 | DB16: 1 | DC16: 1 | DK16: [1],[37],[38] | DL16: =VLOOKUP($F16,Activities!$A$9:$I$180,3,FALSE)/$AI16 -> 3380 | DM16: =VLOOKUP($F16,Activities!$A$9:$I$180,4,FALSE)/$AI16 -> 3525.4611 | DN16: =VLOOKUP($F16,Activities!$A$9:$I$180,5,FALSE)/$AI16 -> 3604.2445 | DO16: =VLOOKUP($F16,Activities!$A$9:$I$180,6,FALSE)/$AI16 -> 3646.5185 | DP16: =VLOOKUP($F16,Activities!$A$9:$I$180,7,FALSE)/$AI16 -> 3663.0438 | DQ16: =VLOOKUP($F16,Activities!$A$9:$I$180,8,FALSE)/$AI16 -> 3659.0085 | DR16: =VLOOKUP($F16,Activities!$A$9:$I$180,9,FALSE)/$AI16 -> 3642.8675
A17: Res03_04 | B17: Gebouwde omgeving | C17: Final | D17: Residential | E17: Terrace | F17: Houses - Residential Terrace | G17: House with insulation A - Residential Terrace | H17: [khouses/y] | I17: 12.9 | J17: 12.57 | K17: 12.25 | L17: 8.7 | M17: 8.4 | N17: 1.9 | O17: 1.9 | P17: 0 | Q17: 0 | R17: 0 | S17: 0 | T17: 0 | U17: 0 | V17: 0 | W17: 0 | X17: 0 | Y17: 0 | Z17: 0 | AA17: 0 | AB17: 0 | AC17: 0 | AD17: 0 | AE17: 0.08 | AF17: 0 | AG17: 40 | AH17: 40 | AI17: 1 | AJ17: Operation | AK17: Built Environment | AY17: none | BN17: =IF(SUM(CB14:CB17)<DL17,CB17,MAX(DL17-SUM(CB14:CB16),0)) -> 0 | BU17: =IF(BL17=1,BN17,0) -> 0 | CB17: 380 | CC17: =DM17 -> 3525.4611 | CD17: =DN17 -> 3604.2445 | CE17: =DO17 -> 3646.5185 | CF17: =DP17 -> 3663.0438 | CG17: =DQ17 -> 3659.0085 | CH17: =DR17 -> 3642.8675 | DF17: 1 | DG17: 1 | DH17: 1 | DI17: 1 | DJ17: 1 | DK17: [1],[37],[38] | DL17: =VLOOKUP($F17,Activities!$A$9:$I$180,3,FALSE)/$AI17 -> 3380 | DM17: =VLOOKUP($F17,Activities!$A$9:$I$180,4,FALSE)/$AI17 -> 3525.4611 | DN17: =VLOOKUP($F17,Activities!$A$9:$I$180,5,FALSE)/$AI17 -> 3604.2445 | DO17: =VLOOKUP($F17,Activities!$A$9:$I$180,6,FALSE)/$AI17 -> 3646.5185 | DP17: =VLOOKUP($F17,Activities!$A$9:$I$180,7,FALSE)/$AI17 -> 3663.0438 | DQ17: =VLOOKUP($F17,Activities!$A$9:$I$180,8,FALSE)/$AI17 -> 3659.0085 | DR17: =VLOOKUP($F17,Activities!$A$9:$I$180,9,FALSE)/$AI17 -> 3642.8675
A18: Res03_05 | B18: Gebouwde omgeving | C18: Final | D18: Residential | E18: Terrace | F18: Houses - Residential Terrace | G18: House with insulation A+ - Residential Terrace | H18: [khouses/y] | I18: 15.69 | J18: 14.91 | K18: 14.12 | L18: 10.2 | M18: 9.5 | N18: 3 | O18: 2.5 | P18: 0 | Q18: 0 | R18: 0 | S18: 0 | T18: 0 | U18: 0 | V18: 0 | W18: 0 | X18: 0 | Y18: 0 | Z18: 0 | AA18: 0 | AB18: 0 | AC18: 0 | AD18: 0 | AE18: 0.08 | AF18: 0 | AG18: 40 | AH18: 40 | AI18: 1 | AJ18: Operation | AK18: Built Environment | AY18: none | BN18: =IF(SUM(CB14:CB18)<DL18,CB18,MAX(DL18-SUM(CB14:CB17),0)) -> 0 | BU18: =IF(BL18=1,BN18,0) -> 0 | CB18: 120 | CC18: =DM18 -> 3525.4611 | CD18: =DN18 -> 3604.2445 | CE18: =DO18 -> 3646.5185 | CF18: =DP18 -> 3663.0438 | CG18: =DQ18 -> 3659.0085 | CH18: =DR18 -> 3642.8675 | DF18: 1 | DG18: 1 | DH18: 1 | DI18: 1 | DJ18: 1 | DK18: [1],[37],[38] | DL18: =VLOOKUP($F18,Activities!$A$9:$I$180,3,FALSE)/$AI18 -> 3380 | DM18: =VLOOKUP($F18,Activities!$A$9:$I$180,4,FALSE)/$AI18 -> 3525.4611 | DN18: =VLOOKUP($F18,Activities!$A$9:$I$180,5,FALSE)/$AI18 -> 3604.2445 | DO18: =VLOOKUP($F18,Activities!$A$9:$I$180,6,FALSE)/$AI18 -> 3646.5185 | DP18: =VLOOKUP($F18,Activities!$A$9:$I$180,7,FALSE)/$AI18 -> 3663.0438 | DQ18: =VLOOKUP($F18,Activities!$A$9:$I$180,8,FALSE)/$AI18 -> 3659.0085 | DR18: =VLOOKUP($F18,Activities!$A$9:$I$180,9,FALSE)/$AI18 -> 3642.8675
A19: Res04_01 | B19: Gebouwde omgeving | C19: Final | D19: Residential | E19: Dwellings | F19: Houses - Residential Dwellings | G19: House with insulation GFE - Residential Dwellings | H19: [khouses/y] | I19: 0 | J19: 0 | K19: 0 | L19: 0 | M19: 0 | N19: 0 | O19: 0 | P19: 0 | Q19: 0 | R19: 0 | S19: 0 | T19: 0 | U19: 0 | V19: 0 | W19: 0 | X19: 0 | Y19: 0 | Z19: 0 | AA19: 0 | AB19: 0 | AC19: 0 | AD19: 0 | AE19: 0.08 | AF19: 0 | AG19: 40 | AH19: 40 | AI19: 1 | AJ19: Operation | AK19: Built Environment | AY19: none | BL19: 1 | BN19: =IF(SUM(CB19:CB19)<DL19,CB19,MAX(DL19-SUM(CB19:CB19),0)) -> 500 | BU19: 500 | CB19: 500 | CC19: =DM19 -> 1822.1836 | CD19: =DN19 -> 1862.9039 | CE19: =DO19 -> 1884.7538 | CF19: =DP19 -> 1893.2951 | CG19: =DQ19 -> 1891.2094 | CH19: =DR19 -> 1882.8667 | CX19: 1 | CY19: 1 | CZ19: 1 | DA19: 1 | DB19: 1 | DC19: 1 | DK19: [1],[37],[38] | DL19: =VLOOKUP($F19,Activities!$A$9:$I$180,3,FALSE)/$AI19 -> 1747 | DM19: =VLOOKUP($F19,Activities!$A$9:$I$180,4,FALSE)/$AI19 -> 1822.1836 | DN19: =VLOOKUP($F19,Activities!$A$9:$I$180,5,FALSE)/$AI19 -> 1862.9039 | DO19: =VLOOKUP($F19,Activities!$A$9:$I$180,6,FALSE)/$AI19 -> 1884.7538 | DP19: =VLOOKUP($F19,Activities!$A$9:$I$180,7,FALSE)/$AI19 -> 1893.2951 | DQ19: =VLOOKUP($F19,Activities!$A$9:$I$180,8,FALSE)/$AI19 -> 1891.2094 | DR19: =VLOOKUP($F19,Activities!$A$9:$I$180,9,FALSE)/$AI19 -> 1882.8667
A20: Res04_02 | B20: Gebouwde omgeving | C20: Final | D20: Residential | E20: Dwellings | F20: Houses - Residential Dwellings | G20: House with insulation DC - Residential Dwellings | H20: [khouses/y] | I20: 5.6 | J20: 5.6 | K20: 5.6 | L20: 0 | M20: 0 | N20: 0 | O20: 0 | P20: 0 | Q20: 0 | R20: 0 | S20: 0 | T20: 0 | U20: 0 | V20: 0 | W20: 0 | X20: 0 | Y20: 0 | Z20: 0 | AA20: 0 | AB20: 0 | AC20: 0 | AD20: 0 | AE20: 0.08 | AF20: 0 | AG20: 40 | AH20: 40 | AI20: 1 | AJ20: Operation | AK20: Built Environment | AY20: none | BL20: 1 | BN20: 500 | BU20: 500 | CB20: 810 | CC20: =DM20 -> 1822.1836 | CD20: =DN20 -> 1862.9039 | CE20: =DO20 -> 1884.7538 | CF20: =DP20 -> 1893.2951 | CG20: =DQ20 -> 1891.2094 | CH20: =DR20 -> 1882.8667 | CY20: 1 | CZ20: 1 | DA20: 1 | DB20: 1 | DC20: 1 | DK20: [12] | DL20: =VLOOKUP($F20,Activities!$A$9:$I$180,3,FALSE)/$AI20 -> 1747 | DM20: =VLOOKUP($F20,Activities!$A$9:$I$180,4,FALSE)/$AI20 -> 1822.1836 | DN20: =VLOOKUP($F20,Activities!$A$9:$I$180,5,FALSE)/$AI20 -> 1862.9039 | DO20: =VLOOKUP($F20,Activities!$A$9:$I$180,6,FALSE)/$AI20 -> 1884.7538 | DP20: =VLOOKUP($F20,Activities!$A$9:$I$180,7,FALSE)/$AI20 -> 1893.2951 | DQ20: =VLOOKUP($F20,Activities!$A$9:$I$180,8,FALSE)/$AI20 -> 1891.2094 | DR20: =VLOOKUP($F20,Activities!$A$9:$I$180,9,FALSE)/$AI20 -> 1882.8667
A21: Res04_03 | B21: Gebouwde omgeving | C21: Final | D21: Residential | E21: Dwellings | F21: Houses - Residential Dwellings | G21: House with insulation B - Residential Dwellings | H21: [khouses/y] | I21: 17.19 | J21: 17.19 | K21: 17.19 | L21: 11.6 | M21: 11.6 | N21: 0 | O21: 0 | P21: 0 | Q21: 0 | R21: 0 | S21: 0 | T21: 0 | U21: 0 | V21: 0 | W21: 0 | X21: 0 | Y21: 0 | Z21: 0 | AA21: 0 | AB21: 0 | AC21: 0 | AD21: 0 | AE21: 0.08 | AF21: 0 | AG21: 40 | AH21: 40 | AI21: 1 | AJ21: Operation | AK21: Built Environment | AY21: none | BL21: 1 | BN21: 500 | BU21: 500 | CB21: 710 | CC21: =DM21 -> 1822.1836 | CD21: =DN21 -> 1862.9039 | CE21: =DO21 -> 1884.7538 | CF21: =DP21 -> 1893.2951 | CG21: =DQ21 -> 1891.2094 | CH21: =DR21 -> 1882.8667 | CZ21: 1 | DA21: 1 | DB21: 1 | DC21: 1 | DK21: [1],[12] | DL21: =VLOOKUP($F21,Activities!$A$9:$I$180,3,FALSE)/$AI21 -> 1747 | DM21: =VLOOKUP($F21,Activities!$A$9:$I$180,4,FALSE)/$AI21 -> 1822.1836 | DN21: =VLOOKUP($F21,Activities!$A$9:$I$180,5,FALSE)/$AI21 -> 1862.9039 | DO21: =VLOOKUP($F21,Activities!$A$9:$I$180,6,FALSE)/$AI21 -> 1884.7538 | DP21: =VLOOKUP($F21,Activities!$A$9:$I$180,7,FALSE)/$AI21 -> 1893.2951 | DQ21: =VLOOKUP($F21,Activities!$A$9:$I$180,8,FALSE)/$AI21 -> 1891.2094 | DR21: =VLOOKUP($F21,Activities!$A$9:$I$180,9,FALSE)/$AI21 -> 1882.8667
A22: Res04_04 | B22: Gebouwde omgeving | C22: Final | D22: Residential | E22: Dwellings | F22: Houses - Residential Dwellings | G22: House with insulation A - Residential Dwellings | H22: [khouses/y] | I22: 23.09 | J22: 22.51 | K22: 21.93 | L22: 15.8 | M22: 15 | N22: 3.4 | O22: 3.4 | P22: 0 | Q22: 0 | R22: 0 | S22: 0 | T22: 0 | U22: 0 | V22: 0 | W22: 0 | X22: 0 | Y22: 0 | Z22: 0 | AA22: 0 | AB22: 0 | AC22: 0 | AD22: 0 | AE22: 0.08 | AF22: 0 | AG22: 40 | AH22: 40 | AI22: 1 | AJ22: Operation | AK22: Built Environment | AY22: none | BN22: 100 | BU22: 100 | CB22: 260 | CC22: =DM22 -> 1822.1836 | CD22: =DN22 -> 1862.9039 | CE22: =DO22 -> 1884.7538 | CF22: =DP22 -> 1893.2951 | CG22: =DQ22 -> 1891.2094 | CH22: =DR22 -> 1882.8667 | DF22: 1 | DG22: 1 | DH22: 1 | DI22: 1 | DJ22: 1 | DK22: [1],[12] | DL22: =VLOOKUP($F22,Activities!$A$9:$I$180,3,FALSE)/$AI22 -> 1747 | DM22: =VLOOKUP($F22,Activities!$A$9:$I$180,4,FALSE)/$AI22 -> 1822.1836 | DN22: =VLOOKUP($F22,Activities!$A$9:$I$180,5,FALSE)/$AI22 -> 1862.9039 | DO22: =VLOOKUP($F22,Activities!$A$9:$I$180,6,FALSE)/$AI22 -> 1884.7538 | DP22: =VLOOKUP($F22,Activities!$A$9:$I$180,7,FALSE)/$AI22 -> 1893.2951 | DQ22: =VLOOKUP($F22,Activities!$A$9:$I$180,8,FALSE)/$AI22 -> 1891.2094 | DR22: =VLOOKUP($F22,Activities!$A$9:$I$180,9,FALSE)/$AI22 -> 1882.8667
A23: Res04_05 | B23: Gebouwde omgeving | C23: Final | D23: Residential | E23: Dwellings | F23: Houses - Residential Dwellings | G23: House with insulation A+ - Residential Dwellings | H23: [khouses/y] | I23: 28.28 | J23: 26.86 | K23: 25.45 | L23: 18.6 | M23: 18 | N23: 6 | O23: 5 | P23: 0 | Q23: 0 | R23: 0 | S23: 0 | T23: 0 | U23: 0 | V23: 0 | W23: 0 | X23: 0 | Y23: 0 | Z23: 0 | AA23: 0 | AB23: 0 | AC23: 0 | AD23: 0 | AE23: 0.08 | AF23: 0 | AG23: 40 | AH23: 40 | AI23: 1 | AJ23: Operation | AK23: Built Environment | AY23: none | BN23: 100 | BU23: 100 | CB23: 160 | CC23: =DM23 -> 1822.1836 | CD23: =DN23 -> 1862.9039 | CE23: =DO23 -> 1884.7538 | CF23: =DP23 -> 1893.2951 | CG23: =DQ23 -> 1891.2094 | CH23: =DR23 -> 1882.8667 | DF23: 1 | DG23: 1 | DH23: 1 | DI23: 1 | DJ23: 1 | DK23: [1],[D] | DL23: =VLOOKUP($F23,Activities!$A$9:$I$180,3,FALSE)/$AI23 -> 1747 | DM23: =VLOOKUP($F23,Activities!$A$9:$I$180,4,FALSE)/$AI23 -> 1822.1836 | DN23: =VLOOKUP($F23,Activities!$A$9:$I$180,5,FALSE)/$AI23 -> 1862.9039 | DO23: =VLOOKUP($F23,Activities!$A$9:$I$180,6,FALSE)/$AI23 -> 1884.7538 | DP23: =VLOOKUP($F23,Activities!$A$9:$I$180,7,FALSE)/$AI23 -> 1893.2951 | DQ23: =VLOOKUP($F23,Activities!$A$9:$I$180,8,FALSE)/$AI23 -> 1891.2094 | DR23: =VLOOKUP($F23,Activities!$A$9:$I$180,9,FALSE)/$AI23 -> 1882.8667
A24: Ser01_01 | B24: Gebouwde omgeving | C24: Final | D24: Services | E24: Appliances | F24: Electricity demand - Services | G24: Dummy standard electricity consumption - Services | H24: [PJ/y] | I24: 0 | J24: 0 | K24: 0 | L24: 0 | M24: 0 | N24: 0 | O24: 0 | P24: 0 | Q24: 0 | R24: 0 | S24: 0 | T24: 0 | U24: 0 | V24: 0 | W24: 0 | X24: 0 | Y24: 0 | Z24: 0 | AA24: 0 | AB24: 0 | AC24: 0 | AD24: 0 | AE24: 0.08 | AF24: 0 | AG24: 1 | AH24: 1 | AI24: 1 | AJ24: Operation | AK24: Standard Load | AY24: none | BL24: 1 | BN24: =DL24 -> 124.9 | BU24: =IF(BL24=1,BN24,0) -> 124.9 | CB24: =DL24 -> 124.9 | CC24: =DM24 -> 127.18872 | CD24: =DN24 -> 138.74361 | CE24: =DO24 -> 148.80423 | CF24: =DP24 -> 160.86911 | CG24: =DQ24 -> 175.1944 | CH24: =DR24 -> 190.288 | DK24: [39] | DL24: =VLOOKUP($F24,Activities!$A$9:$I$180,3,FALSE)/$AI24 -> 124.9 | DM24: =VLOOKUP($F24,Activities!$A$9:$I$180,4,FALSE)/$AI24 -> 127.18872 | DN24: =VLOOKUP($F24,Activities!$A$9:$I$180,5,FALSE)/$AI24 -> 138.74361 | DO24: =VLOOKUP($F24,Activities!$A$9:$I$180,6,FALSE)/$AI24 -> 148.80423 | DP24: =VLOOKUP($F24,Activities!$A$9:$I$180,7,FALSE)/$AI24 -> 160.86911 | DQ24: =VLOOKUP($F24,Activities!$A$9:$I$180,8,FALSE)/$AI24 -> 175.1944 | DR24: =VLOOKUP($F24,Activities!$A$9:$I$180,9,FALSE)/$AI24 -> 190.288
A25: Ser01_02 | B25: Gebouwde omgeving | C25: Final | D25: Services | E25: Appliances | F25: Electricity demand - Services | G25: Flexible standard electricity consumption - Services | H25: [PJ/y] | I25: 0.5 | J25: 0.5 | K25: 0.5 | L25: 0.3 | M25: 0.1 | N25: 0 | O25: 0 | P25: 0 | Q25: 0 | R25: 0 | S25: 0 | T25: 0 | U25: 0 | V25: 0 | W25: 0 | X25: 0 | Y25: 0 | Z25: 0 | AA25: 0 | AB25: 0 | AC25: 0 | AD25: 0 | AE25: 0.08 | AF25: 0 | AG25: 15 | AH25: 15 | AI25: 1 | AJ25: Operation | AK25: Standard Load | AY25: DR shifting | AZ25: Electricity NL - LV | BA25: 1 | BC25: 1 day [d] | BD25: 0.02 | BE25: 0.8 | BN25: =CB25 -> 0.5 | BU25: =IF(BL25=1,BN25,0) -> 0 | CB25: 0.5 | CC25: 1 | CD25: 2 | CE25: 4 | CF25: 10 | CG25: 20 | CH25: 40 | DK25: [39] | DL25: =VLOOKUP($F25,Activities!$A$9:$I$180,3,FALSE)/$AI25 -> 124.9 | DM25: =VLOOKUP($F25,Activities!$A$9:$I$180,4,FALSE)/$AI25 -> 127.18872 | DN25: =VLOOKUP($F25,Activities!$A$9:$I$180,5,FALSE)/$AI25 -> 138.74361 | DO25: =VLOOKUP($F25,Activities!$A$9:$I$180,6,FALSE)/$AI25 -> 148.80423 | DP25: =VLOOKUP($F25,Activities!$A$9:$I$180,7,FALSE)/$AI25 -> 160.86911 | DQ25: =VLOOKUP($F25,Activities!$A$9:$I$180,8,FALSE)/$AI25 -> 175.1944 | DR25: =VLOOKUP($F25,Activities!$A$9:$I$180,9,FALSE)/$AI25 -> 190.288
A26: Ser02_01 | B26: Gebouwde omgeving | C26: Final | D26: Services | E26: Buildings | F26: Space - Services | G26: Space with insulation GFE - Services | H26: [Mm2/y] | I26: 0 | J26: 0 | K26: 0 | L26: 0 | M26: 0 | N26: 0 | O26: 0 | P26: 0 | Q26: 0.32 | R26: 0.32 | S26: 0.32 | T26: 0.32 | U26: 0.32 | V26: 0.32 | W26: 0.32 | X26: 0 | Y26: 0 | Z26: 0 | AA26: 0 | AB26: 0 | AC26: 0 | AD26: 0 | AE26: 0.08 | AF26: 0 | AG26: 25 | AH26: 25 | AI26: 1 | AJ26: Operation | AK26: Built Environment | AY26: none | BL26: 1 | BN26: =IF(SUM(CB26:CB26)<DL26,CB26,MAX(DL26-SUM(CB26:CB26),0)) -> 190 | BU26: 135 | CB26: 190 | CC26: =DM26 -> 446.76845 | CD26: =DN26 -> 487.35663 | CE26: =DO26 -> 522.696 | CF26: =DP26 -> 565.07562 | CG26: =DQ26 -> 615.39523 | CH26: =DR26 -> 668.41365 | CX26: 1 | CY26: 1 | CZ26: 1 | DA26: 1 | DB26: 1 | DC26: 1 | DK26: [39] | DL26: =VLOOKUP($F26,Activities!$A$9:$I$180,3,FALSE)/$AI26 -> 438.729 | DM26: =VLOOKUP($F26,Activities!$A$9:$I$180,4,FALSE)/$AI26 -> 446.76845 | DN26: =VLOOKUP($F26,Activities!$A$9:$I$180,5,FALSE)/$AI26 -> 487.35663 | DO26: =VLOOKUP($F26,Activities!$A$9:$I$180,6,FALSE)/$AI26 -> 522.696 | DP26: =VLOOKUP($F26,Activities!$A$9:$I$180,7,FALSE)/$AI26 -> 565.07562 | DQ26: =VLOOKUP($F26,Activities!$A$9:$I$180,8,FALSE)/$AI26 -> 615.39523 | DR26: =VLOOKUP($F26,Activities!$A$9:$I$180,9,FALSE)/$AI26 -> 668.41365
A27: Ser02_02 | B27: Gebouwde omgeving | C27: Final | D27: Services | E27: Buildings | F27: Space - Services | G27: Space with insulation DC - Services | H27: [Mm2/y] | I27: 21.9 | J27: 21.9 | K27: 21.9 | L27: 0 | M27: 0 | N27: 0 | O27: 0 | P27: 0 | Q27: 0.32 | R27: 0.32 | S27: 0.32 | T27: 0.32 | U27: 0.32 | V27: 0.32 | W27: 0.32 | X27: 0 | Y27: 0 | Z27: 0 | AA27: 0 | AB27: 0 | AC27: 0 | AD27: 0 | AE27: 0.08 | AF27: 0 | AG27: 25 | AH27: 25 | AI27: 1 | AJ27: Operation | AK27: Built Environment | AY27: none | BL27: 1 | BN27: =IF(SUM(CB26:CB27)<DL27,CB27,MAX(DL27-SUM(CB26:CB26),0)) -> 100 | BU27: =IF(BL27=1,BN27,0) -> 100 | CB27: 100 | CC27: =DM27 -> 446.76845 | CD27: =DN27 -> 487.35663 | CE27: =DO27 -> 522.696 | CF27: =DP27 -> 565.07562 | CG27: =DQ27 -> 615.39523 | CH27: =DR27 -> 668.41365 | CY27: 1 | CZ27: 1 | DA27: 1 | DB27: 1 | DC27: 1 | DK27: [1] | DL27: =VLOOKUP($F27,Activities!$A$9:$I$180,3,FALSE)/$AI27 -> 438.729 | DM27: =VLOOKUP($F27,Activities!$A$9:$I$180,4,FALSE)/$AI27 -> 446.76845 | DN27: =VLOOKUP($F27,Activities!$A$9:$I$180,5,FALSE)/$AI27 -> 487.35663 | DO27: =VLOOKUP($F27,Activities!$A$9:$I$180,6,FALSE)/$AI27 -> 522.696 | DP27: =VLOOKUP($F27,Activities!$A$9:$I$180,7,FALSE)/$AI27 -> 565.07562 | DQ27: =VLOOKUP($F27,Activities!$A$9:$I$180,8,FALSE)/$AI27 -> 615.39523 | DR27: =VLOOKUP($F27,Activities!$A$9:$I$180,9,FALSE)/$AI27 -> 668.41365
A28: Ser02_03 | B28: Gebouwde omgeving | C28: Final | D28: Services | E28: Buildings | F28: Space - Services | G28: Space with insulation B - Services | H28: [Mm2/y] | I28: 95.3 | J28: 95.3 | K28: 95.3 | L28: 73.1 | M28: 73.1 | N28: 22 | O28: 22 | P28: 0 | Q28: 0.32 | R28: 0.32 | S28: 0.32 | T28: 0.32 | U28: 0.32 | V28: 0.32 | W28: 0.32 | X28: 0 | Y28: 0 | Z28: 0 | AA28: 0 | AB28: 0 | AC28: 0 | AD28: 0 | AE28: 0.08 | AF28: 0 | AG28: 25 | AH28: 25 | AI28: 1 | AJ28: Operation | AK28: Built Environment | AY28: none | BN28: =IF(SUM(CB26:CB28)<DL28,CB28,MAX(DL28-SUM(CB26:CB27),0)) -> 148.729 | BU28: 180 | CB28: 210 | CC28: =DM28 -> 446.76845 | CD28: =DN28 -> 487.35663 | CE28: =DO28 -> 522.696 | CF28: =DP28 -> 565.07562 | CG28: =DQ28 -> 615.39523 | CH28: =DR28 -> 668.41365 | CZ28: 1 | DA28: 1 | DB28: 1 | DC28: 1 | DK28: [1],[12] | DL28: =VLOOKUP($F28,Activities!$A$9:$I$180,3,FALSE)/$AI28 -> 438.729 | DM28: =VLOOKUP($F28,Activities!$A$9:$I$180,4,FALSE)/$AI28 -> 446.76845 | DN28: =VLOOKUP($F28,Activities!$A$9:$I$180,5,FALSE)/$AI28 -> 487.35663 | DO28: =VLOOKUP($F28,Activities!$A$9:$I$180,6,FALSE)/$AI28 -> 522.696 | DP28: =VLOOKUP($F28,Activities!$A$9:$I$180,7,FALSE)/$AI28 -> 565.07562 | DQ28: =VLOOKUP($F28,Activities!$A$9:$I$180,8,FALSE)/$AI28 -> 615.39523 | DR28: =VLOOKUP($F28,Activities!$A$9:$I$180,9,FALSE)/$AI28 -> 668.41365
A29: Ser02_04 | B29: Gebouwde omgeving | C29: Final | D29: Services | E29: Buildings | F29: Space - Services | G29: Space with insulation A - Services | H29: [Mm2/y] | I29: 109.9 | J29: 107.2 | K29: 104.5 | L29: 82.6 | M29: 77.7 | N29: 26 | O29: 24 | P29: 0 | Q29: 0.32 | R29: 0.32 | S29: 0.32 | T29: 0.32 | U29: 0.32 | V29: 0.32 | W29: 0.32 | X29: 0 | Y29: 0 | Z29: 0 | AA29: 0 | AB29: 0 | AC29: 0 | AD29: 0 | AE29: 0.08 | AF29: 0 | AG29: 25 | AH29: 25 | AI29: 1 | AJ29: Operation | AK29: Built Environment | AY29: none | BN29: =IF(SUM(CB26:CB29)<DL29,CB29,MAX(DL29-SUM(CB26:CB28),0)) -> 0 | BQ29: 0 | BR29: 0 | BT29: 0 | BU29: =IF(BL29=1,BN29,0) -> 0 | CB29: 10 | CC29: =DM29 -> 446.76845 | CD29: =DN29 -> 487.35663 | CE29: =DO29 -> 522.696 | CF29: =DP29 -> 565.07562 | CG29: =DQ29 -> 615.39523 | CH29: =DR29 -> 668.41365 | DF29: 1 | DG29: 1 | DH29: 1 | DI29: 1 | DJ29: 1 | DK29: [12] | DL29: =VLOOKUP($F29,Activities!$A$9:$I$180,3,FALSE)/$AI29 -> 438.729 | DM29: =VLOOKUP($F29,Activities!$A$9:$I$180,4,FALSE)/$AI29 -> 446.76845 | DN29: =VLOOKUP($F29,Activities!$A$9:$I$180,5,FALSE)/$AI29 -> 487.35663 | DO29: =VLOOKUP($F29,Activities!$A$9:$I$180,6,FALSE)/$AI29 -> 522.696 | DP29: =VLOOKUP($F29,Activities!$A$9:$I$180,7,FALSE)/$AI29 -> 565.07562 | DQ29: =VLOOKUP($F29,Activities!$A$9:$I$180,8,FALSE)/$AI29 -> 615.39523 | DR29: =VLOOKUP($F29,Activities!$A$9:$I$180,9,FALSE)/$AI29 -> 668.41365
